Workbook

Sheet 说明
A1: AIVC / 知微 Chronoid — 5000 万元融资 12 个月预算模拟
A2: 单位：人民币万元。本模型为测算工具，全部假设需团队与财务顾问核对后才能对外引用。
A4: 如何使用
A5: 1. 只改「假设」表和「人员」表里的蓝色数字（黄色底 = 关键假设）。其他表全部为公式，会自动重算。
A6: 2. 「月度预算」：Plan A 逐月支出，按六大类汇总。
A7: 3. 「汇总」：资金分配、准备金、单例成本、里程碑节点的累计支出。
A8: 4. 「PlanB情景」：准备金动用规则、三个情景下的现金余额与跑道月数。
A10: 颜色约定
A11: 蓝色字 = 手动输入的假设；黑色字 = 公式；绿色字 = 引用其他工作表；黄色底 = 关键假设，请优先核对。
A13: 口径说明
A14: · 12 个月内不计任何收入（保守口径）：首个付费项目即使落地，也只作为上行空间，不抵减支出。
A15: · 病例成本在入组当月一次性计入（简化）；实际上患者 T1（复发）数据可能晚于 12 个月产生。
... A17: · 价格基于国内一线城市生物医药初创企业的常见市场价区间估算，未经报价核实。【待核】

Sheet 假设
A1: 关键假设（蓝色可改）
A3: 参数 | B3: 数值 | C3: 单位 | D3: 说明 / 依据
A4: 融资与准备金
A5: 本轮融资额 | B5: 5000 | C5: 万元 | D5: 用户口径：5000 万元覆盖 12 个月
A6: Plan B 准备金目标比例 | B6: 0.2 | C6: % | D6: 建议 20%–25%：生物医药早期项目的融资周期通常 6–9 个月，需留出过桥资金
A7: 实验室与设备
A8: 设备采购总额 | B8: 800 | C8: 万元 | D8: 高内涵成像、长时程活细胞成像、培养箱 / 生物安全柜 / 离心机等基础设备【待核：以报价为准】
A9: 设备采购：第 1 个月占比 | B9: 0.5 | C9: %
A10: 设备采购：第 2 个月占比 | B10: 0.3 | C10: %
A11: 设备采购：第 3 个月占比 | B11: 0.2 | C11: % | D11: 三个月占比之和应为 100%
A12: 实验室装修（第 1 个月一次性） | B12: 150 | C12: 万元 | D12: 约 500 m² P2 级细胞实验室
A13: 实验室面积 | B13: 500 | C13: m²
A14: 实验室租金 | B14: 4.5 | C14: 元/m²/天 | D14: 园区实验室租金区间估算【待核】
A15: 通用实验耗材（第 2 个月起） | B15: 8 | C15: 万元/月 | D15: 与具体病例无关的耗材、试剂
A16: 设备维保费率（第 4 个月起） | B16: 0.05 | C16: %/年 | D16: 按设备总额计
A17: 配对病例单例成本
A18: 类器官建模成功率 | B18: 0.7 | C18: % | D18: 失败病例只发生「样本获取 + 建模」成本【待补充：团队历史成功率】
A19: 样本获取与临床随访 | B19: 1.5 | C19: 万元/例 | D19: 采样、病理、医院端数据整理与随访
A20: 类器官建立与扩增 | B20: 2 | C20: 万元/例 | D20: 培养基、基质胶、建库与质控
A21: 扰动实验（多药物 × 多剂量 × 多时间点） | B21: 3 | C21: 万元/成功例 | D21: 统一 SOP 下的扰动面板
A22: 单细胞测序（4 个样本/例） | B22: 4 | C22: 万元/成功例 | D22: 患者 T0 / PDO T0 / PDO T1 / 患者 T1，约 1 万元/样本
A23: bulk RNA + WES | B23: 1.7 | C23: 万元/成功例 | D23: bulk RNA 约 8 条件 × 0.1；WES 约 3 样本 × 0.3
A24: 蛋白组 + 代谢组 | B24: 1.6 | C24: 万元/成功例 | D24: 约 4 样本 × 0.4
A25: 空间转录组（按 50% 病例做） | B25: 1.5 | C25: 万元/成功例 | D25: 约 3 万元/样本 × 50%
A26: 成像与功能表型 | B26: 0.8 | C26: 万元/成功例 | D26: 高内涵 / 活细胞成像运行耗材
A27: 回顾性验证样本数（第 8–11 个月） | B27: 30 | C27: 例 | D27: 利用已有样本库做药物响应回顾性验证（第 12 个月里程碑）
A28: 回顾性验证单例成本 | B28: 3 | C28: 万元/例
A29: 数据与算力
A30: 云 GPU 开始月份 | B30: 2 | C30: 月
A31: 云 GPU 满负荷月份 | B31: 5 | C31: 月 | D31: 之前按 50% 计
A32: 云 GPU 满负荷月费 | B32: 15 | C32: 万元/月 | D32: 约 8 卡训练集群的云租用【待核】
A33: 数据平台搭建（第 2 个月一次性） | B33: 60 | C33: 万元 | D33: LIMS、数据湖，扩展现有 Verqura 系统
A34: 数据平台运维（第 3 个月起） | B34: 3 | C34: 万元/月 | D34: 存储、备份、等保
A35: 软件许可 | B35: 40 | C35: 万元/年 | D35: 分析软件、图像处理、协作工具
A36: 外部数据 / 数据库授权（第 4 个月一次性） | B36: 30 | C36: 万元
A37: 临床合作、合规与知识产权
A38: 合作医院数 | B38: 4 | C38: 家 | D38: 【待补充：合作中心名单与协议状态】
A39: 单中心项目年费 | B39: 40 | C39: 万元/年 | D39: 含伦理审查、数据管理、研究护士支持
A40: 人类遗传资源审批 / 伦理合规咨询（第 1–3 个月） | B40: 40 | C40: 万元 | D40: 遗传办审批或备案、知情同意文件
A41: 数据安全与出境合规（第 4 个月） | B41: 30 | C41: 万元 | D41: 数据出境安全评估 / 标准合同、等保
...

Sheet 人员
A1: 人员计划（月末在岗人数；蓝色可改）
A2: 年度人力成本 = 年薪 + 社保公积金等（单位：万元/人/年）。M0 列固定为 0，用于计算第 1 个月的新增人数。
A4: 岗位 | B4: 年度人力成本 (万元/人) | C4: M0 | D4: M1 | E4: M2 | F4: M3 | G4: M4 | H4: M5 | I4: M6 | J4: M7 | K4: M8 | L4: M9 | M4: M10 | N4: M11 | O4: M12 | P4: 人月合计 | Q4: 12 个月成本 (万元)
A5: 创始团队（CEO / CTO / ML 负责人 / 运营） | B5: 45 | C5: 0 | D5: 4 | E5: 4 | F5: 4 | G5: 4 | H5: 4 | I5: 4 | J5: 4 | K5: 4 | L5: 4 | M5: 4 | N5: 4 | O5: 4 | P5: =SUM(D5:O5) -> 48 | Q5: =B5*P5/12 -> 180
A6: 资深科学家（类器官 / 肿瘤生物学） | B6: 55 | C6: 0 | D6: 1 | E6: 1 | F6: 2 | G6: 2 | H6: 2 | I6: 2 | J6: 2 | K6: 2 | L6: 2 | M6: 2 | N6: 2 | O6: 2 | P6: =SUM(D6:O6) -> 22 | Q6: =B6*P6/12 -> 100.83333
A7: 实验技术员 / 研究助理 | B7: 18 | C7: 0 | D7: 2 | E7: 4 | F7: 4 | G7: 6 | H7: 6 | I7: 6 | J7: 8 | K7: 8 | L7: 10 | M7: 10 | N7: 10 | O7: 10 | P7: =SUM(D7:O7) -> 84 | Q7: =B7*P7/12 -> 126
A8: 生物信息 / 数据工程师 | B8: 40 | C8: 0 | D8: 0 | E8: 1 | F8: 2 | G8: 2 | H8: 3 | I8: 3 | J8: 3 | K8: 3 | L8: 3 | M8: 3 | N8: 3 | O8: 3 | P8: =SUM(D8:O8) -> 29 | Q8: =B8*P8/12 -> 96.666667
A9: 机器学习工程师 | B9: 55 | C9: 0 | D9: 0 | E9: 1 | F9: 1 | G9: 2 | H9: 2 | I9: 3 | J9: 3 | K9: 3 | L9: 4 | M9: 4 | N9: 4 | O9: 4 | P9: =SUM(D9:O9) -> 31 | Q9: =B9*P9/12 -> 142.08333
A10: 临床研究协调员（CRC） | B10: 15 | C10: 0 | D10: 0 | E10: 1 | F10: 2 | G10: 2 | H10: 3 | I10: 3 | J10: 3 | K10: 3 | L10: 3 | M10: 3 | N10: 3 | O10: 3 | P10: =SUM(D10:O10) -> 29 | Q10: =B10*P10/12 -> 36.25
A11: 质量 / 注册与合规 | B11: 40 | C11: 0 | D11: 0 | E11: 0 | F11: 0 | G11: 1 | H11: 1 | I11: 1 | J11: 1 | K11: 1 | L11: 1 | M11: 1 | N11: 1 | O11: 1 | P11: =SUM(D11:O11) -> 9 | Q11: =B11*P11/12 -> 30
A12: 商务拓展（BD） | B12: 45 | C12: 0 | D12: 0 | E12: 0 | F12: 0 | G12: 1 | H12: 1 | I12: 1 | J12: 2 | K12: 2 | L12: 2 | M12: 2 | N12: 2 | O12: 2 | P12: =SUM(D12:O12) -> 15 | Q12: =B12*P12/12 -> 56.25
A13: 行政 / 财务 / HR | B13: 20 | C13: 0 | D13: 1 | E13: 1 | F13: 2 | G13: 2 | H13: 2 | I13: 2 | J13: 2 | K13: 2 | L13: 2 | M13: 2 | N13: 2 | O13: 2 | P13: =SUM(D13:O13) -> 22 | Q13: =B13*P13/12 -> 36.666667
A14: 在岗人数合计 | C14: =SUM(C5:C13) -> 0 | D14: =SUM(D5:D13) -> 8 | E14: =SUM(E5:E13) -> 13 | F14: =SUM(F5:F13) -> 17 | G14: =SUM(G5:G13) -> 22 | H14: =SUM(H5:H13) -> 24 | I14: =SUM(I5:I13) -> 25 | J14: =SUM(J5:J13) -> 28 | ... Q14: =SUM(Q5:Q13) -> 804.75
A15: 当月人力成本（万元） | D15: =SUMPRODUCT($B$5:$B$13,D5:D13)/12 -> 24.25 | E15: =SUMPRODUCT($B$5:$B$13,E5:E13)/12 -> 36.416667 | F15: =SUMPRODUCT($B$5:$B$13,F5:F13)/12 -> 47.25 | G15: =SUMPRODUCT($B$5:$B$13,G5:G13)/12 -> 61.916667 | H15: =SUMPRODUCT($B$5:$B$13,H5:H13)/12 -> 66.5 | I15: =SUMPRODUCT($B$5:$B$13,I5:I13)/12 -> 71.083333 | J15: =SUMPRODUCT($B$5:$B$13,J5:J13)/12 -> 77.833333 | K15: =SUMPRODUCT($B$5:$B$13,K5:K13)/12 -> 77.833333 | ... O15: =SUMPRODUCT($B$5:$B$13,O5:O13)/12 -> 85.416667 | Q15: =SUM(D15:O15) -> 804.75
A16: 当月招聘费用（万元） | D16: =假设!$B$53*SUMPRODUCT($B$5:$B$13,(D5:D13>C5:C13)*(D5:D13-C5:C13)) -> 29.1 | E16: =假设!$B$53*SUMPRODUCT($B$5:$B$13,(E5:E13>D5:D13)*(E5:E13-D5:D13)) -> 14.6 | F16: =假设!$B$53*SUMPRODUCT($B$5:$B$13,(F5:F13>E5:E13)*(F5:F13-E5:E13)) -> 13 | G16: =假设!$B$53*SUMPRODUCT($B$5:$B$13,(G5:G13>F5:F13)*(G5:G13-F5:F13)) -> 17.6 | H16: =假设!$B$53*SUMPRODUCT($B$5:$B$13,(H5:H13>G5:G13)*(H5:H13-G5:G13)) -> 5.5 | I16: =假设!$B$53*SUMPRODUCT($B$5:$B$13,(I5:I13>H5:H13)*(I5:I13-H5:H13)) -> 5.5 | J16: =假设!$B$53*SUMPRODUCT($B$5:$B$13,(J5:J13>I5:I13)*(J5:J13-I5:I13)) -> 8.1 | K16: =假设!$B$53*SUMPRODUCT($B$5:$B$13,(K5:K13>J5:J13)*(K5:K13-J5:J13)) -> 0 | ... O16: =假设!$B$53*SUMPRODUCT($B$5:$B$13,(O5:O13>N5:N13)*(O5:O13-N5:N13)) -> 0 | Q16: =SUM(D16:O16) -> 102.5

Sheet 月度预算
A1: Plan A 月度预算（万元）
A2: 第 4 行为月份序号；第 5 行病例入组数为输入（蓝色）。其余为公式。
A3: 类别 | B3: 项目 | C3: M1 | D3: M2 | E3: M3 | F3: M4 | G3: M5 | H3: M6 | I3: M7 | J3: M8 | K3: M9 | L3: M10 | M3: M11 | N3: M12 | O3: 12 个月合计
B4: 月份序号 | C4: 1 | D4: 2 | E4: 3 | F4: 4 | G4: 5 | H4: 6 | I4: 7 | J4: 8 | K4: 9 | L4: 10 | M4: 11 | N4: 12
B5: 新入组病例数（例） | C5: 0 | D5: 0 | E5: 2 | F5: 3 | G5: 4 | H5: 5 | I5: 8 | J5: 8 | K5: 9 | L5: 9 | M5: 9 | N5: 9 | O5: =SUM(C5:N5) -> 66
B6: 其中成功建模（例） | C6: =C5*假设!$B$18 -> 0 | D6: =D5*假设!$B$18 -> 0 | E6: =E5*假设!$B$18 -> 1.4 | F6: =F5*假设!$B$18 -> 2.1 | G6: =G5*假设!$B$18 -> 2.8 | H6: =H5*假设!$B$18 -> 3.5 | I6: =I5*假设!$B$18 -> 5.6 | J6: =J5*假设!$B$18 -> 5.6 | ... N6: =N5*假设!$B$18 -> 6.3 | O6: =SUM(C6:N6) -> 46.2
A8: 人员 | B8: 人员薪酬（含社保公积金） | C8: =人员!D15 -> 24.25 | D8: =人员!E15 -> 36.416667 | E8: =人员!F15 -> 47.25 | F8: =人员!G15 -> 61.916667 | G8: =人员!H15 -> 66.5 | H8: =人员!I15 -> 71.083333 | I8: =人员!J15 -> 77.833333 | J8: =人员!K15 -> 77.833333 | ... N8: =人员!O15 -> 85.416667 | O8: =SUM(C8:N8) -> 804.75
B9: 招聘费用 | C9: =人员!D16 -> 29.1 | D9: =人员!E16 -> 14.6 | E9: =人员!F16 -> 13 | F9: =人员!G16 -> 17.6 | G9: =人员!H16 -> 5.5 | H9: =人员!I16 -> 5.5 | I9: =人员!J16 -> 8.1 | J9: =人员!K16 -> 0 | ... N9: =人员!O16 -> 0 | O9: =SUM(C9:N9) -> 102.5
B10: 人员 小计 | C10: =SUM(C8:C9) -> 53.35 | D10: =SUM(D8:D9) -> 51.016667 | E10: =SUM(E8:E9) -> 60.25 | F10: =SUM(F8:F9) -> 79.516667 | G10: =SUM(G8:G9) -> 72 | H10: =SUM(H8:H9) -> 76.583333 | I10: =SUM(I8:I9) -> 85.933333 | J10: =SUM(J8:J9) -> 77.833333 | ... O10: =SUM(O8:O9) -> 907.25
A12: 实验与样本 | B12: 设备采购 | C12: =假设!$B$8*((C$4=1)*假设!$B$9+(C$4=2)*假设!$B$10+(C$4=3)*假设!$B$11) -> 400 | D12: =假设!$B$8*((D$4=1)*假设!$B$9+(D$4=2)*假设!$B$10+(D$4=3)*假设!$B$11) -> 240 | E12: =假设!$B$8*((E$4=1)*假设!$B$9+(E$4=2)*假设!$B$10+(E$4=3)*假设!$B$11) -> 160 | F12: =假设!$B$8*((F$4=1)*假设!$B$9+(F$4=2)*假设!$B$10+(F$4=3)*假设!$B$11) -> 0 | G12: =假设!$B$8*((G$4=1)*假设!$B$9+(G$4=2)*假设!$B$10+(G$4=3)*假设!$B$11) -> 0 | H12: =假设!$B$8*((H$4=1)*假设!$B$9+(H$4=2)*假设!$B$10+(H$4=3)*假设!$B$11) -> 0 | I12: =假设!$B$8*((I$4=1)*假设!$B$9+(I$4=2)*假设!$B$10+(I$4=3)*假设!$B$11) -> 0 | J12: =假设!$B$8*((J$4=1)*假设!$B$9+(J$4=2)*假设!$B$10+(J$4=3)*假设!$B$11) -> 0 | ... N12: =假设!$B$8*((N$4=1)*假设!$B$9+(N$4=2)*假设!$B$10+(N$4=3)*假设!$B$11) -> 0 | O12: =SUM(C12:N12) -> 800
B13: 实验室装修 | C13: =(C$4=1)*假设!$B$12 -> 150 | D13: =(D$4=1)*假设!$B$12 -> 0 | E13: =(E$4=1)*假设!$B$12 -> 0 | F13: =(F$4=1)*假设!$B$12 -> 0 | G13: =(G$4=1)*假设!$B$12 -> 0 | H13: =(H$4=1)*假设!$B$12 -> 0 | I13: =(I$4=1)*假设!$B$12 -> 0 | J13: =(J$4=1)*假设!$B$12 -> 0 | ... N13: =(N$4=1)*假设!$B$12 -> 0 | O13: =SUM(C13:N13) -> 150
B14: 实验室租金 | C14: =假设!$B$13*假设!$B$14*30/10000 -> 6.75 | D14: =假设!$B$13*假设!$B$14*30/10000 -> 6.75 | E14: =假设!$B$13*假设!$B$14*30/10000 -> 6.75 | F14: =假设!$B$13*假设!$B$14*30/10000 -> 6.75 | G14: =假设!$B$13*假设!$B$14*30/10000 -> 6.75 | H14: =假设!$B$13*假设!$B$14*30/10000 -> 6.75 | I14: =假设!$B$13*假设!$B$14*30/10000 -> 6.75 | J14: =假设!$B$13*假设!$B$14*30/10000 -> 6.75 | ... N14: =假设!$B$13*假设!$B$14*30/10000 -> 6.75 | O14: =SUM(C14:N14) -> 81
B15: 样本获取与类器官建立（全部入组病例） | C15: =C$5*(假设!$B$19+假设!$B$20) -> 0 | D15: =D$5*(假设!$B$19+假设!$B$20) -> 0 | E15: =E$5*(假设!$B$19+假设!$B$20) -> 7 | F15: =F$5*(假设!$B$19+假设!$B$20) -> 10.5 | G15: =G$5*(假设!$B$19+假设!$B$20) -> 14 | H15: =H$5*(假设!$B$19+假设!$B$20) -> 17.5 | I15: =I$5*(假设!$B$19+假设!$B$20) -> 28 | J15: =J$5*(假设!$B$19+假设!$B$20) -> 28 | ... N15: =N$5*(假设!$B$19+假设!$B$20) -> 31.5 | O15: =SUM(C15:N15) -> 231
B16: 扰动实验与多组学读出（成功建模病例） | C16: =C$6*(假设!$B$21+假设!$B$22+假设!$B$23+假设!$B$24+假设!$B$25+假设!$B$26) -> 0 | D16: =D$6*(假设!$B$21+假设!$B$22+假设!$B$23+假设!$B$24+假设!$B$25+假设!$B$26) -> 0 | E16: =E$6*(假设!$B$21+假设!$B$22+假设!$B$23+假设!$B$24+假设!$B$25+假设!$B$26) -> 17.64 | F16: =F$6*(假设!$B$21+假设!$B$22+假设!$B$23+假设!$B$24+假设!$B$25+假设!$B$26) -> 26.46 | G16: =G$6*(假设!$B$21+假设!$B$22+假设!$B$23+假设!$B$24+假设!$B$25+假设!$B$26) -> 35.28 | H16: =H$6*(假设!$B$21+假设!$B$22+假设!$B$23+假设!$B$24+假设!$B$25+假设!$B$26) -> 44.1 | I16: =I$6*(假设!$B$21+假设!$B$22+假设!$B$23+假设!$B$24+假设!$B$25+假设!$B$26) -> 70.56 | J16: =J$6*(假设!$B$21+假设!$B$22+假设!$B$23+假设!$B$24+假设!$B$25+假设!$B$26) -> 70.56 | ... N16: =N$6*(假设!$B$21+假设!$B$22+假设!$B$23+假设!$B$24+假设!$B$25+假设!$B$26) -> 79.38 | O16: =SUM(C16:N16) -> 582.12
B17: 回顾性验证样本 | C17: =AND(C$4>=8,C$4<=11)*假设!$B$27*假设!$B$28/4 -> 0 | D17: =AND(D$4>=8,D$4<=11)*假设!$B$27*假设!$B$28/4 -> 0 | E17: =AND(E$4>=8,E$4<=11)*假设!$B$27*假设!$B$28/4 -> 0 | F17: =AND(F$4>=8,F$4<=11)*假设!$B$27*假设!$B$28/4 -> 0 | G17: =AND(G$4>=8,G$4<=11)*假设!$B$27*假设!$B$28/4 -> 0 | H17: =AND(H$4>=8,H$4<=11)*假设!$B$27*假设!$B$28/4 -> 0 | I17: =AND(I$4>=8,I$4<=11)*假设!$B$27*假设!$B$28/4 -> 0 | J17: =AND(J$4>=8,J$4<=11)*假设!$B$27*假设!$B$28/4 -> 22.5 | ... N17: =AND(N$4>=8,N$4<=11)*假设!$B$27*假设!$B$28/4 -> 0 | O17: =SUM(C17:N17) -> 90
B18: 通用实验耗材 | C18: =(C$4>=2)*假设!$B$15 -> 0 | D18: =(D$4>=2)*假设!$B$15 -> 8 | E18: =(E$4>=2)*假设!$B$15 -> 8 | F18: =(F$4>=2)*假设!$B$15 -> 8 | G18: =(G$4>=2)*假设!$B$15 -> 8 | H18: =(H$4>=2)*假设!$B$15 -> 8 | I18: =(I$4>=2)*假设!$B$15 -> 8 | J18: =(J$4>=2)*假设!$B$15 -> 8 | ... N18: =(N$4>=2)*假设!$B$15 -> 8 | O18: =SUM(C18:N18) -> 88
B19: 设备维保 | C19: =(C$4>=4)*假设!$B$8*假设!$B$16/12 -> 0 | D19: =(D$4>=4)*假设!$B$8*假设!$B$16/12 -> 0 | E19: =(E$4>=4)*假设!$B$8*假设!$B$16/12 -> 0 | F19: =(F$4>=4)*假设!$B$8*假设!$B$16/12 -> 3.3333333 | G19: =(G$4>=4)*假设!$B$8*假设!$B$16/12 -> 3.3333333 | H19: =(H$4>=4)*假设!$B$8*假设!$B$16/12 -> 3.3333333 | I19: =(I$4>=4)*假设!$B$8*假设!$B$16/12 -> 3.3333333 | J19: =(J$4>=4)*假设!$B$8*假设!$B$16/12 -> 3.3333333 | ... N19: =(N$4>=4)*假设!$B$8*假设!$B$16/12 -> 3.3333333 | O19: =SUM(C19:N19) -> 30
B20: 实验与样本 小计 | C20: =SUM(C12:C19) -> 556.75 | D20: =SUM(D12:D19) -> 254.75 | E20: =SUM(E12:E19) -> 199.39 | F20: =SUM(F12:F19) -> 55.043333 | G20: =SUM(G12:G19) -> 67.363333 | H20: =SUM(H12:H19) -> 79.683333 | I20: =SUM(I12:I19) -> 116.64333 | J20: =SUM(J12:J19) -> 139.14333 | ... O20: =SUM(O12:O19) -> 2052.12
A22: 数据与算力 | B22: 云 GPU 算力 | C22: =IF(C$4<假设!$B$30,0,IF(C$4<假设!$B$31,0.5,1))*假设!$B$32 -> 0 | D22: =IF(D$4<假设!$B$30,0,IF(D$4<假设!$B$31,0.5,1))*假设!$B$32 -> 7.5 | E22: =IF(E$4<假设!$B$30,0,IF(E$4<假设!$B$31,0.5,1))*假设!$B$32 -> 7.5 | F22: =IF(F$4<假设!$B$30,0,IF(F$4<假设!$B$31,0.5,1))*假设!$B$32 -> 7.5 | G22: =IF(G$4<假设!$B$30,0,IF(G$4<假设!$B$31,0.5,1))*假设!$B$32 -> 15 | H22: =IF(H$4<假设!$B$30,0,IF(H$4<假设!$B$31,0.5,1))*假设!$B$32 -> 15 | I22: =IF(I$4<假设!$B$30,0,IF(I$4<假设!$B$31,0.5,1))*假设!$B$32 -> 15 | J22: =IF(J$4<假设!$B$30,0,IF(J$4<假设!$B$31,0.5,1))*假设!$B$32 -> 15 | ... N22: =IF(N$4<假设!$B$30,0,IF(N$4<假设!$B$31,0.5,1))*假设!$B$32 -> 15 | O22: =SUM(C22:N22) -> 142.5
B23: 数据平台搭建 | C23: =(C$4=2)*假设!$B$33 -> 0 | D23: =(D$4=2)*假设!$B$33 -> 60 | E23: =(E$4=2)*假设!$B$33 -> 0 | F23: =(F$4=2)*假设!$B$33 -> 0 | G23: =(G$4=2)*假设!$B$33 -> 0 | H23: =(H$4=2)*假设!$B$33 -> 0 | I23: =(I$4=2)*假设!$B$33 -> 0 | J23: =(J$4=2)*假设!$B$33 -> 0 | ... N23: =(N$4=2)*假设!$B$33 -> 0 | O23: =SUM(C23:N23) -> 60
B24: 数据平台运维 | C24: =(C$4>=3)*假设!$B$34 -> 0 | D24: =(D$4>=3)*假设!$B$34 -> 0 | E24: =(E$4>=3)*假设!$B$34 -> 3 | F24: =(F$4>=3)*假设!$B$34 -> 3 | G24: =(G$4>=3)*假设!$B$34 -> 3 | H24: =(H$4>=3)*假设!$B$34 -> 3 | I24: =(I$4>=3)*假设!$B$34 -> 3 | J24: =(J$4>=3)*假设!$B$34 -> 3 | ... N24: =(N$4>=3)*假设!$B$34 -> 3 | O24: =SUM(C24:N24) -> 30
B25: 软件许可 | C25: =假设!$B$35/12 -> 3.3333333 | D25: =假设!$B$35/12 -> 3.3333333 | E25: =假设!$B$35/12 -> 3.3333333 | F25: =假设!$B$35/12 -> 3.3333333 | G25: =假设!$B$35/12 -> 3.3333333 | H25: =假设!$B$35/12 -> 3.3333333 | I25: =假设!$B$35/12 -> 3.3333333 | J25: =假设!$B$35/12 -> 3.3333333 | ... N25: =假设!$B$35/12 -> 3.3333333 | O25: =SUM(C25:N25) -> 40
B26: 外部数据 / 数据库授权 | C26: =(C$4=4)*假设!$B$36 -> 0 | D26: =(D$4=4)*假设!$B$36 -> 0 | E26: =(E$4=4)*假设!$B$36 -> 0 | F26: =(F$4=4)*假设!$B$36 -> 30 | G26: =(G$4=4)*假设!$B$36 -> 0 | H26: =(H$4=4)*假设!$B$36 -> 0 | I26: =(I$4=4)*假设!$B$36 -> 0 | J26: =(J$4=4)*假设!$B$36 -> 0 | ... N26: =(N$4=4)*假设!$B$36 -> 0 | O26: =SUM(C26:N26) -> 30
B27: 数据与算力 小计 | C27: =SUM(C22:C26) -> 3.3333333 | D27: =SUM(D22:D26) -> 70.833333 | E27: =SUM(E22:E26) -> 13.833333 | F27: =SUM(F22:F26) -> 43.833333 | G27: =SUM(G22:G26) -> 21.333333 | H27: =SUM(H22:H26) -> 21.333333 | I27: =SUM(I22:I26) -> 21.333333 | J27: =SUM(J22:J26) -> 21.333333 | ... O27: =SUM(O22:O26) -> 302.5
A29: 临床合作、合规与IP | B29: 合作医院项目费 | C29: =(C$4>=2)*假设!$B$38*假设!$B$39/12 -> 0 | D29: =(D$4>=2)*假设!$B$38*假设!$B$39/12 -> 13.333333 | E29: =(E$4>=2)*假设!$B$38*假设!$B$39/12 -> 13.333333 | F29: =(F$4>=2)*假设!$B$38*假设!$B$39/12 -> 13.333333 | G29: =(G$4>=2)*假设!$B$38*假设!$B$39/12 -> 13.333333 | H29: =(H$4>=2)*假设!$B$38*假设!$B$39/12 -> 13.333333 | I29: =(I$4>=2)*假设!$B$38*假设!$B$39/12 -> 13.333333 | J29: =(J$4>=2)*假设!$B$38*假设!$B$39/12 -> 13.333333 | ... N29: =(N$4>=2)*假设!$B$38*假设!$B$39/12 -> 13.333333 | O29: =SUM(C29:N29) -> 146.66667
B30: 人类遗传资源 / 伦理合规 | C30: =(C$4<=3)*假设!$B$40/3 -> 13.333333 | D30: =(D$4<=3)*假设!$B$40/3 -> 13.333333 | E30: =(E$4<=3)*假设!$B$40/3 -> 13.333333 | F30: =(F$4<=3)*假设!$B$40/3 -> 0 | G30: =(G$4<=3)*假设!$B$40/3 -> 0 | H30: =(H$4<=3)*假设!$B$40/3 -> 0 | I30: =(I$4<=3)*假设!$B$40/3 -> 0 | J30: =(J$4<=3)*假设!$B$40/3 -> 0 | ... N30: =(N$4<=3)*假设!$B$40/3 -> 0 | O30: =SUM(C30:N30) -> 40
B31: 数据安全与出境合规 | C31: =(C$4=4)*假设!$B$41 -> 0 | D31: =(D$4=4)*假设!$B$41 -> 0 | E31: =(E$4=4)*假设!$B$41 -> 0 | F31: =(F$4=4)*假设!$B$41 -> 30 | G31: =(G$4=4)*假设!$B$41 -> 0 | H31: =(H$4=4)*假设!$B$41 -> 0 | I31: =(I$4=4)*假设!$B$41 -> 0 | J31: =(J$4=4)*假设!$B$41 -> 0 | ... N31: =(N$4=4)*假设!$B$41 -> 0 | O31: =SUM(C31:N31) -> 30
B32: 专利申请 | C32: =假设!$B$42*假设!$B$43/12 -> 4 | D32: =假设!$B$42*假设!$B$43/12 -> 4 | E32: =假设!$B$42*假设!$B$43/12 -> 4 | F32: =假设!$B$42*假设!$B$43/12 -> 4 | G32: =假设!$B$42*假设!$B$43/12 -> 4 | H32: =假设!$B$42*假设!$B$43/12 -> 4 | I32: =假设!$B$42*假设!$B$43/12 -> 4 | J32: =假设!$B$42*假设!$B$43/12 -> 4 | ... N32: =假设!$B$42*假设!$B$43/12 -> 4 | O32: =SUM(C32:N32) -> 48
B33: 法律、审计、财务 | C33: =假设!$B$44/12 -> 3.3333333 | D33: =假设!$B$44/12 -> 3.3333333 | E33: =假设!$B$44/12 -> 3.3333333 | F33: =假设!$B$44/12 -> 3.3333333 | G33: =假设!$B$44/12 -> 3.3333333 | H33: =假设!$B$44/12 -> 3.3333333 | I33: =假设!$B$44/12 -> 3.3333333 | J33: =假设!$B$44/12 -> 3.3333333 | ... N33: =假设!$B$44/12 -> 3.3333333 | O33: =SUM(C33:N33) -> 40
B34: 临床合作、合规与IP 小计 | C34: =SUM(C29:C33) -> 20.666667 | D34: =SUM(D29:D33) -> 34 | E34: =SUM(E29:E33) -> 34 | F34: =SUM(F29:F33) -> 50.666667 | G34: =SUM(G29:G33) -> 20.666667 | H34: =SUM(H29:H33) -> 20.666667 | I34: =SUM(I29:I33) -> 20.666667 | J34: =SUM(J29:J33) -> 20.666667 | ... O34: =SUM(O29:O33) -> 304.66667
A36: 商务与运营 | B36: 办公租金 | C36: =假设!$B$46*假设!$B$47*30/10000 -> 3.6 | D36: =假设!$B$46*假设!$B$47*30/10000 -> 3.6 | E36: =假设!$B$46*假设!$B$47*30/10000 -> 3.6 | F36: =假设!$B$46*假设!$B$47*30/10000 -> 3.6 | G36: =假设!$B$46*假设!$B$47*30/10000 -> 3.6 | H36: =假设!$B$46*假设!$B$47*30/10000 -> 3.6 | I36: =假设!$B$46*假设!$B$47*30/10000 -> 3.6 | J36: =假设!$B$46*假设!$B$47*30/10000 -> 3.6 | ... N36: =假设!$B$46*假设!$B$47*30/10000 -> 3.6 | O36: =SUM(C36:N36) -> 43.2
B37: 差旅 | C37: =假设!$B$48 -> 4 | D37: =假设!$B$48 -> 4 | E37: =假设!$B$48 -> 4 | F37: =假设!$B$48 -> 4 | G37: =假设!$B$48 -> 4 | H37: =假设!$B$48 -> 4 | I37: =假设!$B$48 -> 4 | J37: =假设!$B$48 -> 4 | ... N37: =假设!$B$48 -> 4 | O37: =SUM(C37:N37) -> 48
B38: 学术会议与市场 | C38: =假设!$B$49/12 -> 3.3333333 | D38: =假设!$B$49/12 -> 3.3333333 | E38: =假设!$B$49/12 -> 3.3333333 | F38: =假设!$B$49/12 -> 3.3333333 | G38: =假设!$B$49/12 -> 3.3333333 | H38: =假设!$B$49/12 -> 3.3333333 | I38: =假设!$B$49/12 -> 3.3333333 | J38: =假设!$B$49/12 -> 3.3333333 | ... N38: =假设!$B$49/12 -> 3.3333333 | O38: =SUM(C38:N38) -> 40
B39: BD 试点项目投入 | C39: =(C$4>=7)*假设!$B$50/6 -> 0 | D39: =(D$4>=7)*假设!$B$50/6 -> 0 | E39: =(E$4>=7)*假设!$B$50/6 -> 0 | F39: =(F$4>=7)*假设!$B$50/6 -> 0 | G39: =(G$4>=7)*假设!$B$50/6 -> 0 | H39: =(H$4>=7)*假设!$B$50/6 -> 0 | I39: =(I$4>=7)*假设!$B$50/6 -> 16.666667 | J39: =(J$4>=7)*假设!$B$50/6 -> 16.666667 | ... N39: =(N$4>=7)*假设!$B$50/6 -> 16.666667 | O39: =SUM(C39:N39) -> 100
B40: 行政、IT、保险杂费 | C40: =假设!$B$51 -> 2 | D40: =假设!$B$51 -> 2 | E40: =假设!$B$51 -> 2 | F40: =假设!$B$51 -> 2 | G40: =假设!$B$51 -> 2 | H40: =假设!$B$51 -> 2 | I40: =假设!$B$51 -> 2 | J40: =假设!$B$51 -> 2 | ... N40: =假设!$B$51 -> 2 | O40: =SUM(C40:N40) -> 24
B41: 商务与运营 小计 | C41: =SUM(C36:C40) -> 12.933333 | D41: =SUM(D36:D40) -> 12.933333 | E41: =SUM(E36:E40) -> 12.933333 | F41: =SUM(F36:F40) -> 12.933333 | G41: =SUM(G36:G40) -> 12.933333 | H41: =SUM(H36:H40) -> 12.933333 | I41: =SUM(I36:I40) -> 29.6 | J41: =SUM(J36:J40) -> 29.6 | ... O41: =SUM(O36:O40) -> 255.2
A43: 不可预见费 | B43: Plan A 内部不可预见费 | C43: =假设!$B$52*(C10+C20+C27+C34+C41) -> 19.411 | D43: =假设!$B$52*(D10+D20+D27+D34+D41) -> 12.706 | E43: =假设!$B$52*(E10+E20+E27+E34+E41) -> 9.6122 | F43: =假设!$B$52*(F10+F20+F27+F34+F41) -> 7.2598 | G43: =假设!$B$52*(G10+G20+G27+G34+G41) -> 5.8289 | H43: =假设!$B$52*(H10+H20+H27+H34+H41) -> 6.336 | I43: =假设!$B$52*(I10+I20+I27+I34+I41) -> 8.2253 | J43: =假设!$B$52*(J10+J20+J27+J34+J41) -> 8.6573 | ... N43: =假设!$B$52*(N10+N20+N27+N34+N41) -> 8.5794 | O43: =SUM(C43:N43) -> 114.6521
A45: 合计 | B45: Plan A 当月支出 | C45: =C10+C20+C27+C34+C41+C43 -> 666.44433 | D45: =D10+D20+D27+D34+D41+D43 -> 436.23933 | E45: =E10+E20+E27+E34+E41+E43 -> 330.01887 | F45: =F10+F20+F27+F34+F41+F43 -> 249.25313 | G45: =G10+G20+G27+G34+G41+G43 -> 200.12557 | H45: =H10+H20+H27+H34+H41+H43 -> 217.536 | I45: =I10+I20+I27+I34+I41+I43 -> 282.40197 | J45: =J10+J20+J27+J34+J41+J43 -> 297.23397 | ... O45: =O10+O20+O27+O34+O41+O43 -> 3936.3888
B46: Plan A 累计支出 | C46: =SUM($C$45:C45) -> 666.44433 | D46: =SUM($C$45:D45) -> 1102.6837 | E46: =SUM($C$45:E45) -> 1432.7025 | F46: =SUM($C$45:F45) -> 1681.9557 | G46: =SUM($C$45:G45) -> 1882.0812 | H46: =SUM($C$45:H45) -> 2099.6172 | I46: =SUM($C$45:I45) -> 2382.0192 | J46: =SUM($C$45:J45) -> 2679.2532 | ... N46: =SUM($C$45:N45) -> 3936.3888
B47: 账面现金余额（含准备金） | C47: =假设!$B$5-C46 -> 4333.5557 | D47: =假设!$B$5-D46 -> 3897.3163 | E47: =假设!$B$5-E46 -> 3567.2975 | F47: =假设!$B$5-F46 -> 3318.0443 | G47: =假设!$B$5-G46 -> 3117.9188 | H47: =假设!$B$5-H46 -> 2900.3828 | I47: =假设!$B$5-I46 -> 2617.9808 | J47: =假设!$B$5-J46 -> 2320.7468 | ... N47: =假设!$B$5-N46 -> 1063.6112

Sheet 汇总
A1: 预算汇总与准备金（万元）
A3: 项目 | B3: 金额（万元） | C3: 占融资额 | D3: 占 Plan A 支出 | E3: 对应里程碑 / 用途
A4: 人员 | B4: =月度预算!O10 -> 907.25 | C4: =B4/假设!$B$5 -> 0.18145 | D4: =B4/$B$10 -> 0.23047774 | E4: 团队按飞轮环节逐步扩充（人数见「人员」表）
A5: 实验与样本 | B5: =月度预算!O20 -> 2052.12 | C5: =B5/假设!$B$5 -> 0.410424 | D5: =B5/$B$10 -> 0.52132046 | E5: 第 6 个月首批配对队列；第 12 个月回顾性验证 + 前瞻性评分启动
A6: 数据与算力 | B6: =月度预算!O27 -> 302.5 | C6: =B6/假设!$B$5 -> 0.0605 | D6: =B6/$B$10 -> 0.076847084 | E6: AIVC 模型训练与数据平台；第 12 个月具备 v1 模型训练条件
A7: 临床合作、合规与IP | B7: =月度预算!O34 -> 304.66667 | C7: =B7/假设!$B$5 -> 0.060933333 | D7: =B7/$B$10 -> 0.077397504 | E7: 合作中心、遗传资源与伦理合规、数据出境合规、专利布局
A8: 商务与运营 | B8: =月度预算!O41 -> 255.2 | C8: =B8/假设!$B$5 -> 0.05104 | D8: =B8/$B$10 -> 0.064830995 | E8: 首个付费 / 联合开发项目的试点与商务拓展
A9: 不可预见费 | B9: =月度预算!O43 -> 114.6521 | C9: =B9/假设!$B$5 -> 0.02293042 | D9: =B9/$B$10 -> 0.029126214 | E9: Plan A 内部的小额超支缓冲（与准备金分开）
A10: Plan A 12 个月支出合计 | B10: =SUM(B4:B9) -> 3936.3888 | C10: =B10/假设!$B$5 -> 0.78727775 | D10: =B10/B10 -> 1
A11: Plan B 准备金（独立账户） | B11: =假设!$B$5-B10 -> 1063.6112 | C11: =B11/假设!$B$5 -> 0.21272225 | E11: 仅在触发条件出现、经董事会批准后动用（见 PlanB情景）
A12: 本轮融资额 | B12: =假设!$B$5 -> 5000 | C12: =B12/假设!$B$5 -> 1
A14: 检查：准备金是否达到目标比例 | B14: =IF(C11>=假设!$B$6,"达标","未达标：需压缩 Plan A") -> 达标 | C14: =假设!$B$6 -> 0.2 | D14: 目标比例
A16: 关键指标
A17: 12 个月入组病例 | B17: =月度预算!O5 -> 66
A18: 其中成功建模（配对病例） | B18: =月度预算!O6 -> 46.2
A19: 第 12 个月在岗人数 | B19: =人员!O14 -> 31
A20: 单例直接实验成本（按成功病例分摊） | B20: =(月度预算!O15+月度预算!O16)/B18 -> 17.6 | E20: 样本获取 + 建模 + 扰动 + 多组学，含失败病例的分摊
A21: Plan A 月均支出 | B21: =B10/12 -> 328.0324
A22: Plan A 第 10–12 个月月均支出 | B22: =AVERAGE(月度预算!L45:N45) -> 310.0094 | E22: 进入稳态后的月度消耗，用于估算下一轮融资规模
A23: 第 6 个月累计支出（Level 1 闸门） | B23: =月度预算!H46 -> 2099.6172 | E23: 闸门未过时，剩余资金 = 融资额 − 本行
A24: 第 12 个月累计支出 | B24: =月度预算!N46 -> 3936.3888
A25: 下一轮融资参考规模（稳态月耗 × 24 个月） | B25: =B22*24 -> 7440.2256 | E25: 仅为量级参考：下一轮通常覆盖 18–24 个月且团队会扩大

Sheet PlanB情景
A1: Plan B：准备金动用规则与情景测算（万元）
A3: 一、维持期月度支出（Plan B 最低运转成本，蓝色可改）
A4: 项目 | B4: 数值 | C4: 单位 | D4: 说明
A5: 保留人员数 | B5: 14 | C5: 人 | D5: 创始团队 + 关键科学家 + 核心实验 / 数据 / 模型人员
A6: 保留人员人均年度人力成本 | B6: 40 | C6: 万元/人/年
A7: 最低实验支出（耗材 + 维持建模） | B7: 15 | C7: 万元/月 | D7: 保持类器官库存活与少量病例入组
A8: 最低算力与数据平台 | B8: 5 | C8: 万元/月
A9: 最低运营（租金之外的行政、差旅、合规） | B9: 8 | C9: 万元/月
A10: 实验室 + 办公租金 | B10: =(假设!$B$13*假设!$B$14+假设!$B$46*假设!$B$47)*30/10000 -> 10.35 | C10: 万元/月
A11: 维持期月度支出合计 | B11: =$B$5*$B$6/12+$B$7+$B$8+$B$9+$B$10 -> 85.016667 | C11: 万元/月
A13: 二、Plan B-1 削减参数（科学闸门未过时启用，蓝色可改）
A14: 项目 | B14: 数值 | C14: 单位 | D14: 说明
A15: 触发月份（从该月起执行削减） | B15: 7 | C15: 月 | D15: 第 6 个月 Level 1 闸门评估未通过
A16: 实验与样本支出削减比例 | B16: 0.5 | C16: % | D16: 病例入组减半，集中在建模成功率最高的瘤种
A17: 数据与算力支出削减比例 | B17: 0.3 | C17: %
A18: 商务与运营支出削减比例 | B18: 0.5 | C18: % | D18: 暂停 BD 试点，压缩会议与差旅
A19: 人员：冻结招聘，维持触发前一个月的人力成本
A21: 三、逐月现金测算
A22: 情景 | B22: 项目 | C22: M1 | D22: M2 | E22: M3 | F22: M4 | G22: M5 | H22: M6 | I22: M7 | J22: M8 | K22: M9 | L22: M10 | M22: M11 | N22: M12 | O22: 12 个月合计
B23: 月份序号 | C23: 1 | D23: 2 | E23: 3 | F23: 4 | G23: 5 | H23: 6 | I23: 7 | J23: 8 | K23: 9 | L23: 10 | M23: 11 | N23: 12
A24: 情景 A：Plan A 正常推进 | B24: 当月支出 | C24: =月度预算!C45 -> 666.44433 | D24: =月度预算!D45 -> 436.23933 | E24: =月度预算!E45 -> 330.01887 | F24: =月度预算!F45 -> 249.25313 | G24: =月度预算!G45 -> 200.12557 | H24: =月度预算!H45 -> 217.536 | I24: =月度预算!I45 -> 282.40197 | J24: =月度预算!J45 -> 297.23397 | ... N24: =月度预算!N45 -> 294.5594 | O24: =SUM(C24:N24) -> 3936.3888
A25: 情景 B：第 6 个月闸门未过，第 7 个月起削减 | B25: 当月支出 | C25: =IF(C$23<$B$15,月度预算!C45,INDEX(月度预算!$C$8:$N$8,$B$15-1)+月度预算!C20*(1-$B$16)+月度预算!C27*(1-$B$17)+月度预算!C34+月度预算!C41*(1-$B$18)) -> 666.44433 | D25: =IF(D$23<$B$15,月度预算!D45,INDEX(月度预算!$C$8:$N$8,$B$15-1)+月度预算!D20*(1-$B$16)+月度预算!D27*(1-$B$17)+月度预算!D34+月度预算!D41*(1-$B$18)) -> 436.23933 | E25: =IF(E$23<$B$15,月度预算!E45,INDEX(月度预算!$C$8:$N$8,$B$15-1)+月度预算!E20*(1-$B$16)+月度预算!E27*(1-$B$17)+月度预算!E34+月度预算!E41*(1-$B$18)) -> 330.01887 | F25: =IF(F$23<$B$15,月度预算!F45,INDEX(月度预算!$C$8:$N$8,$B$15-1)+月度预算!F20*(1-$B$16)+月度预算!F27*(1-$B$17)+月度预算!F34+月度预算!F41*(1-$B$18)) -> 249.25313 | G25: =IF(G$23<$B$15,月度预算!G45,INDEX(月度预算!$C$8:$N$8,$B$15-1)+月度预算!G20*(1-$B$16)+月度预算!G27*(1-$B$17)+月度预算!G34+月度预算!G41*(1-$B$18)) -> 200.12557 | H25: =IF(H$23<$B$15,月度预算!H45,INDEX(月度预算!$C$8:$N$8,$B$15-1)+月度预算!H20*(1-$B$16)+月度预算!H27*(1-$B$17)+月度预算!H34+月度预算!H41*(1-$B$18)) -> 217.536 | I25: =IF(I$23<$B$15,月度预算!I45,INDEX(月度预算!$C$8:$N$8,$B$15-1)+月度预算!I20*(1-$B$16)+月度预算!I27*(1-$B$17)+月度预算!I34+月度预算!I41*(1-$B$18)) -> 179.805 | J25: =IF(J$23<$B$15,月度预算!J45,INDEX(月度预算!$C$8:$N$8,$B$15-1)+月度预算!J20*(1-$B$16)+月度预算!J27*(1-$B$17)+月度预算!J34+月度预算!J41*(1-$B$18)) -> 191.055 | ... N25: =IF(N$23<$B$15,月度预算!N45,INDEX(月度预算!$C$8:$N$8,$B$15-1)+月度预算!N20*(1-$B$16)+月度预算!N27*(1-$B$17)+月度预算!N34+月度预算!N41*(1-$B$18)) -> 185.965 | O25: =SUM(C25:N25) -> 3248.0872
A26: 情景 C：闸门未过 + 下一轮融资受阻，第 7 个月起直接进入维持期 | B26: 当月支出 | C26: =IF(C$23<$B$15,月度预算!C45,$B$11) -> 666.44433 | D26: =IF(D$23<$B$15,月度预算!D45,$B$11) -> 436.23933 | E26: =IF(E$23<$B$15,月度预算!E45,$B$11) -> 330.01887 | F26: =IF(F$23<$B$15,月度预算!F45,$B$11) -> 249.25313 | G26: =IF(G$23<$B$15,月度预算!G45,$B$11) -> 200.12557 | H26: =IF(H$23<$B$15,月度预算!H45,$B$11) -> 217.536 | I26: =IF(I$23<$B$15,月度预算!I45,$B$11) -> 85.016667 | J26: =IF(J$23<$B$15,月度预算!J45,$B$11) -> 85.016667 | ... N26: =IF(N$23<$B$15,月度预算!N45,$B$11) -> 85.016667 | O26: =SUM(C26:N26) -> 2609.7172
A27: 情景 A | B27: 账面现金余额 | C27: =假设!$B$5-SUM($C$24:C24) -> 4333.5557 | D27: =假设!$B$5-SUM($C$24:D24) -> 3897.3163 | E27: =假设!$B$5-SUM($C$24:E24) -> 3567.2975 | F27: =假设!$B$5-SUM($C$24:F24) -> 3318.0443 | G27: =假设!$B$5-SUM($C$24:G24) -> 3117.9188 | H27: =假设!$B$5-SUM($C$24:H24) -> 2900.3828 | I27: =假设!$B$5-SUM($C$24:I24) -> 2617.9808 | J27: =假设!$B$5-SUM($C$24:J24) -> 2320.7468 | ... N27: =假设!$B$5-SUM($C$24:N24) -> 1063.6112
A28: 情景 B | B28: 账面现金余额 | C28: =假设!$B$5-SUM($C$25:C25) -> 4333.5557 | D28: =假设!$B$5-SUM($C$25:D25) -> 3897.3163 | E28: =假设!$B$5-SUM($C$25:E25) -> 3567.2975 | F28: =假设!$B$5-SUM($C$25:F25) -> 3318.0443 | G28: =假设!$B$5-SUM($C$25:G25) -> 3117.9188 | H28: =假设!$B$5-SUM($C$25:H25) -> 2900.3828 | I28: =假设!$B$5-SUM($C$25:I25) -> 2720.5778 | J28: =假设!$B$5-SUM($C$25:J25) -> 2529.5228 | ... N28: =假设!$B$5-SUM($C$25:N25) -> 1751.9128
A29: 情景 C | B29: 账面现金余额 | C29: =假设!$B$5-SUM($C$26:C26) -> 4333.5557 | D29: =假设!$B$5-SUM($C$26:D26) -> 3897.3163 | E29: =假设!$B$5-SUM($C$26:E26) -> 3567.2975 | F29: =假设!$B$5-SUM($C$26:F26) -> 3318.0443 | G29: =假设!$B$5-SUM($C$26:G26) -> 3117.9188 | H29: =假设!$B$5-SUM($C$26:H26) -> 2900.3828 | I29: =假设!$B$5-SUM($C$26:I26) -> 2815.3661 | J29: =假设!$B$5-SUM($C$26:J26) -> 2730.3494 | ... N29: =假设!$B$5-SUM($C$26:N26) -> 2390.2828
A31: 四、情景结果
A32: 情景 | B32: 12 个月支出 | C32: 第 12 个月末现金 | D32: 之后按维持期可再支撑（月） | E32: 总跑道（月） | F32: 说明
A33: 情景 A：Plan A 正常推进 | B33: =O24 -> 3936.3888 | C33: =假设!$B$5-O24 -> 1063.6112 | D33: =IF($B$11>0,C33/$B$11,0) -> 12.51062 | E33: =12+D33 -> 24.51062 | F33: 准备金未动用，作为下一轮融资的过桥资金
A34: 情景 B：闸门未过，收缩 | B34: =O25 -> 3248.0872 | C34: =假设!$B$5-O25 -> 1751.9128 | D34: =IF($B$11>0,C34/$B$11,0) -> 20.606698 | E34: =12+D34 -> 32.606698 | F34: 科学风险出现时收缩，仍完成核心验证，跑道延长
A35: 情景 C：闸门未过 + 融资受阻 | B35: =O26 -> 2609.7172 | C35: =假设!$B$5-O26 -> 2390.2828 | D35: =IF($B$11>0,C35/$B$11,0) -> 28.115461 | E35: =12+D35 -> 40.115461 | F35: 最坏情况：保住团队、类器官库与数据资产，等待融资或战略合作
A37: 五、准备金动用规则（建议写入股东协议 / 董事会议事规则）
A38: 触发条件 1 | B38: 第 6 个月 Level 1 闸门（重复性、周转时间、失败率、培养偏差模型）未达阈值 → 执行情景 B
A39: 触发条件 2 | B39: 第 9 个月仍未拿到下一轮投资意向书（TS），且现金跑道 < 6 个月 → 冻结招聘，准备进入维持期
A40: 触发条件 3 | B40: 第 12 个月首个付费 / 联合开发项目未落地 → 转向类器官检测与研究服务，以服务收入延长跑道
A41: 动用程序 | B41: 准备金存放于独立账户；动用需董事会（含投资人董事）批准，并同步公布收缩方案
A42: 不得动用于 | B42: Plan A 的常规超支（由 Plan A 内部不可预见费覆盖）、新增非核心岗位、未经批准的设备采购
